<?xml version="1.0"?>
<robot xmlns:xacro="http://www.ros.org/wiki/xacro"  >
    <xacro:include filename="inertial_macros.xacro"/>
    <material name="white">
        <color rgba="1.0 1.0 1.0 1.0"/>
    </material>

    <material name="black">
        <color rgba="0.0 0.0 0.0 1.0"/>
    </material>

    <material name="red">
        <color rgba="1.0 0.0 0.0 1.0"/>
    </material>
    <material name="yellow">
        <color rgba="1.0 1.0 0.0 1.0"/>
    </material>

    <material name="blue">
        <color rgba="0.0 1.0 1.0 1.0"/>
    </material>

    <material name="green">
        <color rgba="0.0 1.0 0.0 1.0"/>
    </material>
<link name="base_link">
    
</link>

<joint name="chassis_joint" type="fixed">
    <parent link="base_link"/>
    <child link="chassis"/>
    <origin xyz="-0.0705585 0.0 0.0"/>
</joint>
<link name="chassis">
    <visual>
        <origin xyz="0.128089 0 0.0431217"/>
        <geometry>
            <box size="0.256178 0.149629 0.0862434"/>
        </geometry>
        <material name="white"/>
    </visual>
    <collision>
        <origin xyz="0.128089 0 0.0431217"/>
        <geometry>
            <box size="0.256178 0.149629 0.0862434"/>
        </geometry>     
    </collision>
    <xacro:inertial_box mass="0.5" x="0.256178" y="0.149629" z="0.0862434">
        <origin xyz="0.128089 0 0.0431217" rpy="0.0 0.0 0.0"/>
    </xacro:inertial_box>
</link>
<!-- LEFT WHEEL 1 -->

<joint name="left_wheel_joint" type="continuous">
    <parent link="base_link"/>
    <child link="left_wheel"/>
    <origin xyz="0 0.0941415 0" rpy="-${pi/2} 0 0"/>
    <axis xyz="0 0 1"/>
</joint>

<link name="left_wheel">
    <visual>
        <geometry>
            <cylinder length="0.019327" radius="0.0307448" />
        </geometry>
        <material name="black"/>
    </visual>
    <collision>
        <geometry>
            <cylinder length="0.019327" radius="0.0307448" />
        </geometry>
    </collision>
    <xacro:inertial_cylinder mass="0.05" length="0.019327" radius="0.0307448">
        <origin xyz="0 0 0" rpy="0.0 0.0 0.0"/>
    </xacro:inertial_cylinder>

</link>

<!-- RIGHT WHEEL 1-->

<joint name="right_wheel_joint" type="continuous">
    <parent link="base_link"/>
    <child link="right_wheel"/>
    <origin xyz="0 -0.0941415 0" rpy="${pi/2} 0 0"/>
    <axis xyz="0 0 -1"/>
</joint>

<link name="right_wheel">
    <visual>
        <geometry>
            <cylinder length="0.019327" radius="0.0307448" />
        </geometry>
        <material name="black"/>
    </visual>
    <collision>
        <geometry>
            <cylinder length="0.019327" radius="0.0307448" />
        </geometry>
    </collision>
    <xacro:inertial_cylinder mass="0.05" length="0.019327" radius="0.0307448">
        <origin xyz="0 0 0" rpy="0.0 0.0 0.0"/>
    </xacro:inertial_cylinder>
</link>


<!-- LEFT WHEEL 2-->

<joint name="left_wheel2_joint" type="continuous">
    <parent link="base_link"/>
    <child link="left_wheel2"/>
    <origin xyz="0.115061 0.0941415 0" rpy="-${pi/2} 0 0"/>
    <axis xyz="0 0 1"/>
</joint>

<link name="left_wheel2">
    <visual>
        <geometry>
            <cylinder length="0.019327" radius="0.0307448" />
        </geometry>
        <material name="black"/>
    </visual>
    <collision>
        <geometry>
            <cylinder length="0.019327" radius="0.0307448" />
        </geometry>
    </collision>
    <xacro:inertial_cylinder mass="0.05" length="0.019327" radius="0.0307448">
        <origin xyz="0 0 0" rpy="0.0 0.0 0.0"/>
    </xacro:inertial_cylinder>
</link>

<!-- RIGHT WHEEL 2-->

<joint name="right_wheel2_joint" type="continuous">
    <parent link="base_link"/>
    <child link="right_wheel2"/>
    <origin xyz="0.115061 -0.0941415 0" rpy="${pi/2} 0 0"/>
    <axis xyz="0 0 -1"/>
</joint>

<link name="right_wheel2">
    <visual>
        <geometry>
            <cylinder length="0.019327" radius="0.0307448" />
        </geometry>
        <material name="black"/>
    </visual>
    <collision>
        <geometry>
            <cylinder length="0.019327" radius="0.0307448" />
        </geometry>
    </collision>
    <xacro:inertial_cylinder mass="0.05" length="0.019327" radius="0.0307448">
        <origin xyz="0 0 0" rpy="0.0 0.0 0.0"/>
    </xacro:inertial_cylinder>
</link>

</robot>